Workbook
Name NativeTimeline_Date: #N/A
Name Slicer_Weather_sit: #N/A
Name Slicer_Weekday: #N/A

Sheet Dashboard

Sheet Extract Data_sheet
A1: Extract Data From Dataset_A
A4: date | B4: Weather_sit | C4: Temp | D4: A_Temp | E4: Humidity | F4: Wind_speed | G4: Casual | H4: Registered | I4: Total_Client | K4: Day | L4: Hum Wise | N4: Day Time | O4: =SUMIF(Dataset_A!$S:$S,'Extract Data_sheet'!$N4,Dataset_A!$P:$P) -> 37010 | Q4: Time Based Analisis
A5: 40544 | B5: =AVERAGEIF(Dataset_A!$B:$B,'Extract Data_sheet'!$A5,Dataset_A!I:I) -> 1.5833333 | C5: =AVERAGEIF(Dataset_A!$B:$B,'Extract Data_sheet'!$A5,Dataset_A!J:J) -> 0.34416667 | D5: =AVERAGEIF(Dataset_A!$B:$B,'Extract Data_sheet'!$A5,Dataset_A!K:K) -> 0.31438333 | E5: =AVERAGEIF(Dataset_A!$B:$B,'Extract Data_sheet'!$A5,Dataset_A!L:L) -> 0.80583333 | F5: =AVERAGEIF(Dataset_A!$B:$B,'Extract Data_sheet'!$A5,Dataset_A!M:M) -> 0.16044583 | G5: =SUMIF(Dataset_A!$B:$B,'Extract Data_sheet'!$A5,Dataset_A!N:N) -> 331 | H5: =SUMIF(Dataset_A!$B:$B,'Extract Data_sheet'!$A5,Dataset_A!O:O) -> 654 | I5: =SUMIF(Dataset_A!$B:$B,'Extract Data_sheet'!$A5,Dataset_A!P:P) -> 985 | K5: =TEXT(A5,"dddd") -> Saturday | L5: =IF(E5>=80%,"High Humidity",IF(E5>=50%,"Mid Humidity",IF(E5>=30%,"Low Humidity",""))) -> High Humidity | N5: Evening Time | O5: =SUMIF(Dataset_A!$S:$S,'Extract Data_sheet'!$N5,Dataset_A!$P:$P) -> 10904 | Q5: 19--24 | R5: Evening Time
A6: 40545 | B6: =AVERAGEIF(Dataset_A!$B:$B,'Extract Data_sheet'!$A6,Dataset_A!I:I) -> 1.9565217 | C6: =AVERAGEIF(Dataset_A!$B:$B,'Extract Data_sheet'!$A6,Dataset_A!J:J) -> 0.36347826 | D6: =AVERAGEIF(Dataset_A!$B:$B,'Extract Data_sheet'!$A6,Dataset_A!K:K) -> 0.28984348 | E6: =AVERAGEIF(Dataset_A!$B:$B,'Extract Data_sheet'!$A6,Dataset_A!L:L) -> 0.69608696 | F6: =AVERAGEIF(Dataset_A!$B:$B,'Extract Data_sheet'!$A6,Dataset_A!M:M) -> 0.24853913 | G6: =SUMIF(Dataset_A!$B:$B,'Extract Data_sheet'!$A6,Dataset_A!N:N) -> 131 | H6: =SUMIF(Dataset_A!$B:$B,'Extract Data_sheet'!$A6,Dataset_A!O:O) -> 670 | I6: =SUMIF(Dataset_A!$B:$B,'Extract Data_sheet'!$A6,Dataset_A!P:P) -> 801 | K6: =TEXT(A6,"dddd") -> Sunday | L6: =IF(E6>=80%,"High Humidity",IF(E6>=50%,"Mid Humidity",IF(E6>=30%,"Low Humidity",""))) -> Mid Humidity | N6: Night Time | O6: =SUMIF(Dataset_A!$S:$S,'Extract Data_sheet'!$N6,Dataset_A!$P:$P) -> 10390 | Q6: 0--8 | R6: Night Time
A7: 40546 | B7: =AVERAGEIF(Dataset_A!$B:$B,'Extract Data_sheet'!$A7,Dataset_A!I:I) -> 1 | C7: =AVERAGEIF(Dataset_A!$B:$B,'Extract Data_sheet'!$A7,Dataset_A!J:J) -> 0.19636364 | D7: =AVERAGEIF(Dataset_A!$B:$B,'Extract Data_sheet'!$A7,Dataset_A!K:K) -> 0.16185455 | E7: =AVERAGEIF(Dataset_A!$B:$B,'Extract Data_sheet'!$A7,Dataset_A!L:L) -> 0.43727273 | F7: =AVERAGEIF(Dataset_A!$B:$B,'Extract Data_sheet'!$A7,Dataset_A!M:M) -> 0.24830909 | G7: =SUMIF(Dataset_A!$B:$B,'Extract Data_sheet'!$A7,Dataset_A!N:N) -> 120 | H7: =SUMIF(Dataset_A!$B:$B,'Extract Data_sheet'!$A7,Dataset_A!O:O) -> 1229 | I7: =SUMIF(Dataset_A!$B:$B,'Extract Data_sheet'!$A7,Dataset_A!P:P) -> 1349 | K7: =TEXT(A7,"dddd") -> Monday | L7: =IF(E7>=80%,"High Humidity",IF(E7>=50%,"Mid Humidity",IF(E7>=30%,"Low Humidity",""))) -> Low Humidity | N7: Total Client | O7: =SUM(O4:O6) -> 58304 | Q7: 9--18 | R7: Day Time
A8: 40547 | B8: =AVERAGEIF(Dataset_A!$B:$B,'Extract Data_sheet'!$A8,Dataset_A!I:I) -> 1.0434783 | C8: =AVERAGEIF(Dataset_A!$B:$B,'Extract Data_sheet'!$A8,Dataset_A!J:J) -> 0.2 | D8: =AVERAGEIF(Dataset_A!$B:$B,'Extract Data_sheet'!$A8,Dataset_A!K:K) -> 0.20421739 | E8: =AVERAGEIF(Dataset_A!$B:$B,'Extract Data_sheet'!$A8,Dataset_A!L:L) -> 0.59043478 | F8: =AVERAGEIF(Dataset_A!$B:$B,'Extract Data_sheet'!$A8,Dataset_A!M:M) -> 0.16029565 | G8: =SUMIF(Dataset_A!$B:$B,'Extract Data_sheet'!$A8,Dataset_A!N:N) -> 108 | H8: =SUMIF(Dataset_A!$B:$B,'Extract Data_sheet'!$A8,Dataset_A!O:O) -> 1454 | I8: =SUMIF(Dataset_A!$B:$B,'Extract Data_sheet'!$A8,Dataset_A!P:P) -> 1562 | K8: =TEXT(A8,"dddd") -> Tuesday | L8: =IF(E8>=80%,"High Humidity",IF(E8>=50%,"Mid Humidity",IF(E8>=30%,"Low Humidity",""))) -> Mid Humidity
A9: 40548 | B9: =AVERAGEIF(Dataset_A!$B:$B,'Extract Data_sheet'!$A9,Dataset_A!I:I) -> 1 | C9: =AVERAGEIF(Dataset_A!$B:$B,'Extract Data_sheet'!$A9,Dataset_A!J:J) -> 0.22695652 | D9: =AVERAGEIF(Dataset_A!$B:$B,'Extract Data_sheet'!$A9,Dataset_A!K:K) -> 0.22926957 | E9: =AVERAGEIF(Dataset_A!$B:$B,'Extract Data_sheet'!$A9,Dataset_A!L:L) -> 0.43695652 | F9: =AVERAGEIF(Dataset_A!$B:$B,'Extract Data_sheet'!$A9,Dataset_A!M:M) -> 0.1869 | G9: =SUMIF(Dataset_A!$B:$B,'Extract Data_sheet'!$A9,Dataset_A!N:N) -> 82 | H9: =SUMIF(Dataset_A!$B:$B,'Extract Data_sheet'!$A9,Dataset_A!O:O) -> 1518 | I9: =SUMIF(Dataset_A!$B:$B,'Extract Data_sheet'!$A9,Dataset_A!P:P) -> 1600 | K9: =TEXT(A9,"dddd") -> Wednesday | L9: =IF(E9>=80%,"High Humidity",IF(E9>=50%,"Mid Humidity",IF(E9>=30%,"Low Humidity",""))) -> Low Humidity
A10: 40549 | B10: =AVERAGEIF(Dataset_A!$B:$B,'Extract Data_sheet'!$A10,Dataset_A!I:I) -> 1.3478261 | C10: =AVERAGEIF(Dataset_A!$B:$B,'Extract Data_sheet'!$A10,Dataset_A!J:J) -> 0.20434783 | D10: =AVERAGEIF(Dataset_A!$B:$B,'Extract Data_sheet'!$A10,Dataset_A!K:K) -> 0.2332087 | E10: =AVERAGEIF(Dataset_A!$B:$B,'Extract Data_sheet'!$A10,Dataset_A!L:L) -> 0.51826087 | F10: =AVERAGEIF(Dataset_A!$B:$B,'Extract Data_sheet'!$A10,Dataset_A!M:M) -> 0.089565217 | G10: =SUMIF(Dataset_A!$B:$B,'Extract Data_sheet'!$A10,Dataset_A!N:N) -> 88 | H10: =SUMIF(Dataset_A!$B:$B,'Extract Data_sheet'!$A10,Dataset_A!O:O) -> 1518 | I10: =SUMIF(Dataset_A!$B:$B,'Extract Data_sheet'!$A10,Dataset_A!P:P) -> 1606 | K10: =TEXT(A10,"dddd") -> Thursday | L10: =IF(E10>=80%,"High Humidity",IF(E10>=50%,"Mid Humidity",IF(E10>=30%,"Low Humidity",""))) -> Mid Humidity
A11: 40550 | B11: =AVERAGEIF(Dataset_A!$B:$B,'Extract Data_sheet'!$A11,Dataset_A!I:I) -> 1.6956522 | C11: =AVERAGEIF(Dataset_A!$B:$B,'Extract Data_sheet'!$A11,Dataset_A!J:J) -> 0.19652174 | D11: =AVERAGEIF(Dataset_A!$B:$B,'Extract Data_sheet'!$A11,Dataset_A!K:K) -> 0.20883913 | E11: =AVERAGEIF(Dataset_A!$B:$B,'Extract Data_sheet'!$A11,Dataset_A!L:L) -> 0.49869565 | F11: =AVERAGEIF(Dataset_A!$B:$B,'Extract Data_sheet'!$A11,Dataset_A!M:M) -> 0.16872609 | G11: =SUMIF(Dataset_A!$B:$B,'Extract Data_sheet'!$A11,Dataset_A!N:N) -> 148 | H11: =SUMIF(Dataset_A!$B:$B,'Extract Data_sheet'!$A11,Dataset_A!O:O) -> 1362 | I11: =SUMIF(Dataset_A!$B:$B,'Extract Data_sheet'!$A11,Dataset_A!P:P) -> 1510 | K11: =TEXT(A11,"dddd") -> Friday | L11: =IF(E11>=80%,"High Humidity",IF(E11>=50%,"Mid Humidity",IF(E11>=30%,"Low Humidity",""))) -> Low Humidity | N11: Monday | O11: =SUMIF($K$5:$K$49,$N11,$I$5:$I$49) -> 8450 | Q11: Standard Deviation (Client)
A12: 40551 | B12: =AVERAGEIF(Dataset_A!$B:$B,'Extract Data_sheet'!$A12,Dataset_A!I:I) -> 1.7083333 | C12: =AVERAGEIF(Dataset_A!$B:$B,'Extract Data_sheet'!$A12,Dataset_A!J:J) -> 0.165 | D12: =AVERAGEIF(Dataset_A!$B:$B,'Extract Data_sheet'!$A12,Dataset_A!K:K) -> 0.16225417 | E12: =AVERAGEIF(Dataset_A!$B:$B,'Extract Data_sheet'!$A12,Dataset_A!L:L) -> 0.53583333 | F12: =AVERAGEIF(Dataset_A!$B:$B,'Extract Data_sheet'!$A12,Dataset_A!M:M) -> 0.26680417 | G12: =SUMIF(Dataset_A!$B:$B,'Extract Data_sheet'!$A12,Dataset_A!N:N) -> 68 | H12: =SUMIF(Dataset_A!$B:$B,'Extract Data_sheet'!$A12,Dataset_A!O:O) -> 891 | I12: =SUMIF(Dataset_A!$B:$B,'Extract Data_sheet'!$A12,Dataset_A!P:P) -> 959 | K12: =TEXT(A12,"dddd") -> Saturday | L12: =IF(E12>=80%,"High Humidity",IF(E12>=50%,"Mid Humidity",IF(E12>=30%,"Low Humidity",""))) -> Mid Humidity | N12: Tuesday | O12: =SUMIF($K$5:$K$49,$N12,$I$5:$I$49) -> 8383 | Q12: =STDEV(H5:H49) -> 380.68196
A13: 40552 | B13: =AVERAGEIF(Dataset_A!$B:$B,'Extract Data_sheet'!$A13,Dataset_A!I:I) -> 1 | C13: =AVERAGEIF(Dataset_A!$B:$B,'Extract Data_sheet'!$A13,Dataset_A!J:J) -> 0.13833333 | D13: =AVERAGEIF(Dataset_A!$B:$B,'Extract Data_sheet'!$A13,Dataset_A!K:K) -> 0.116175 | E13: =AVERAGEIF(Dataset_A!$B:$B,'Extract Data_sheet'!$A13,Dataset_A!L:L) -> 0.43416667 | F13: =AVERAGEIF(Dataset_A!$B:$B,'Extract Data_sheet'!$A13,Dataset_A!M:M) -> 0.36195 | G13: =SUMIF(Dataset_A!$B:$B,'Extract Data_sheet'!$A13,Dataset_A!N:N) -> 54 | H13: =SUMIF(Dataset_A!$B:$B,'Extract Data_sheet'!$A13,Dataset_A!O:O) -> 768 | I13: =SUMIF(Dataset_A!$B:$B,'Extract Data_sheet'!$A13,Dataset_A!P:P) -> 822 | K13: =TEXT(A13,"dddd") -> Sunday | L13: =IF(E13>=80%,"High Humidity",IF(E13>=50%,"Mid Humidity",IF(E13>=30%,"Low Humidity",""))) -> Low Humidity | N13: Wednesday | O13: =SUMIF($K$5:$K$49,$N13,$I$5:$I$49) -> 8049
A14: 40553 | B14: =AVERAGEIF(Dataset_A!$B:$B,'Extract Data_sheet'!$A14,Dataset_A!I:I) -> 1.3333333 | C14: =AVERAGEIF(Dataset_A!$B:$B,'Extract Data_sheet'!$A14,Dataset_A!J:J) -> 0.15083333 | D14: =AVERAGEIF(Dataset_A!$B:$B,'Extract Data_sheet'!$A14,Dataset_A!K:K) -> 0.1508875 | E14: =AVERAGEIF(Dataset_A!$B:$B,'Extract Data_sheet'!$A14,Dataset_A!L:L) -> 0.48291667 | F14: =AVERAGEIF(Dataset_A!$B:$B,'Extract Data_sheet'!$A14,Dataset_A!M:M) -> 0.22326667 | G14: =SUMIF(Dataset_A!$B:$B,'Extract Data_sheet'!$A14,Dataset_A!N:N) -> 41 | H14: =SUMIF(Dataset_A!$B:$B,'Extract Data_sheet'!$A14,Dataset_A!O:O) -> 1280 | I14: =SUMIF(Dataset_A!$B:$B,'Extract Data_sheet'!$A14,Dataset_A!P:P) -> 1321 | K14: =TEXT(A14,"dddd") -> Monday | L14: =IF(E14>=80%,"High Humidity",IF(E14>=50%,"Mid Humidity",IF(E14>=30%,"Low Humidity",""))) -> Low Humidity | N14: Thursday | O14: =SUMIF($K$5:$K$49,$N14,$I$5:$I$49) -> 8458 | Q14: Correl (Total Client & Registerd
A15: 40554 | B15: =AVERAGEIF(Dataset_A!$B:$B,'Extract Data_sheet'!$A15,Dataset_A!I:I) -> 2.1818182 | C15: =AVERAGEIF(Dataset_A!$B:$B,'Extract Data_sheet'!$A15,Dataset_A!J:J) -> 0.16909091 | D15: =AVERAGEIF(Dataset_A!$B:$B,'Extract Data_sheet'!$A15,Dataset_A!K:K) -> 0.19146364 | E15: =AVERAGEIF(Dataset_A!$B:$B,'Extract Data_sheet'!$A15,Dataset_A!L:L) -> 0.68636364 | F15: =AVERAGEIF(Dataset_A!$B:$B,'Extract Data_sheet'!$A15,Dataset_A!M:M) -> 0.12213182 | G15: =SUMIF(Dataset_A!$B:$B,'Extract Data_sheet'!$A15,Dataset_A!N:N) -> 43 | H15: =SUMIF(Dataset_A!$B:$B,'Extract Data_sheet'!$A15,Dataset_A!O:O) -> 1220 | I15: =SUMIF(Dataset_A!$B:$B,'Extract Data_sheet'!$A15,Dataset_A!P:P) -> 1263 | K15: =TEXT(A15,"dddd") -> Tuesday | L15: =IF(E15>=80%,"High Humidity",IF(E15>=50%,"Mid Humidity",IF(E15>=30%,"Low Humidity",""))) -> Mid Humidity | N15: Friday | O15: =SUMIF($K$5:$K$49,$N15,$I$5:$I$49) -> 9095 | Q15: =CORREL(I5:I49,H5:H49) -> 0.97275364
A16: 40555 | B16: =AVERAGEIF(Dataset_A!$B:$B,'Extract Data_sheet'!$A16,Dataset_A!I:I) -> 1.0909091 | C16: =AVERAGEIF(Dataset_A!$B:$B,'Extract Data_sheet'!$A16,Dataset_A!J:J) -> 0.17272727 | D16: =AVERAGEIF(Dataset_A!$B:$B,'Extract Data_sheet'!$A16,Dataset_A!K:K) -> 0.16047273 | E16: =AVERAGEIF(Dataset_A!$B:$B,'Extract Data_sheet'!$A16,Dataset_A!L:L) -> 0.59954545 | F16: =AVERAGEIF(Dataset_A!$B:$B,'Extract Data_sheet'!$A16,Dataset_A!M:M) -> 0.30462727 | G16: =SUMIF(Dataset_A!$B:$B,'Extract Data_sheet'!$A16,Dataset_A!N:N) -> 25 | H16: =SUMIF(Dataset_A!$B:$B,'Extract Data_sheet'!$A16,Dataset_A!O:O) -> 1137 | I16: =SUMIF(Dataset_A!$B:$B,'Extract Data_sheet'!$A16,Dataset_A!P:P) -> 1162 | K16: =TEXT(A16,"dddd") -> Wednesday | L16: =IF(E16>=80%,"High Humidity",IF(E16>=50%,"Mid Humidity",IF(E16>=30%,"Low Humidity",""))) -> Mid Humidity | N16: Saturday | O16: =SUMIF($K$5:$K$49,$N16,$I$5:$I$49) -> 7748
A17: 40556 | B17: =AVERAGEIF(Dataset_A!$B:$B,'Extract Data_sheet'!$A17,Dataset_A!I:I) -> 1.0833333 | C17: =AVERAGEIF(Dataset_A!$B:$B,'Extract Data_sheet'!$A17,Dataset_A!J:J) -> 0.165 | D17: =AVERAGEIF(Dataset_A!$B:$B,'Extract Data_sheet'!$A17,Dataset_A!K:K) -> 0.15088333 | E17: =AVERAGEIF(Dataset_A!$B:$B,'Extract Data_sheet'!$A17,Dataset_A!L:L) -> 0.47041667 | F17: =AVERAGEIF(Dataset_A!$B:$B,'Extract Data_sheet'!$A17,Dataset_A!M:M) -> 0.301 | G17: =SUMIF(Dataset_A!$B:$B,'Extract Data_sheet'!$A17,Dataset_A!N:N) -> 38 | H17: =SUMIF(Dataset_A!$B:$B,'Extract Data_sheet'!$A17,Dataset_A!O:O) -> 1368 | I17: =SUMIF(Dataset_A!$B:$B,'Extract Data_sheet'!$A17,Dataset_A!P:P) -> 1406 | K17: =TEXT(A17,"dddd") -> Thursday | L17: =IF(E17>=80%,"High Humidity",IF(E17>=50%,"Mid Humidity",IF(E17>=30%,"Low Humidity",""))) -> Low Humidity | N17: Sunday | O17: =SUMIF($K$5:$K$49,$N17,$I$5:$I$49) -> 8121
A18: 40557 | B18: =AVERAGEIF(Dataset_A!$B:$B,'Extract Data_sheet'!$A18,Dataset_A!I:I) -> 1.0869565 | C18: =AVERAGEIF(Dataset_A!$B:$B,'Extract Data_sheet'!$A18,Dataset_A!J:J) -> 0.16086957 | D18: =AVERAGEIF(Dataset_A!$B:$B,'Extract Data_sheet'!$A18,Dataset_A!K:K) -> 0.18841304 | E18: =AVERAGEIF(Dataset_A!$B:$B,'Extract Data_sheet'!$A18,Dataset_A!L:L) -> 0.53782609 | F18: =AVERAGEIF(Dataset_A!$B:$B,'Extract Data_sheet'!$A18,Dataset_A!M:M) -> 0.12654783 | G18: =SUMIF(Dataset_A!$B:$B,'Extract Data_sheet'!$A18,Dataset_A!N:N) -> 54 | H18: =SUMIF(Dataset_A!$B:$B,'Extract Data_sheet'!$A18,Dataset_A!O:O) -> 1367 | I18: =SUMIF(Dataset_A!$B:$B,'Extract Data_sheet'!$A18,Dataset_A!P:P) -> 1421 | K18: =TEXT(A18,"dddd") -> Friday | L18: =IF(E18>=80%,"High Humidity",IF(E18>=50%,"Mid Humidity",IF(E18>=30%,"Low Humidity",""))) -> Mid Humidity | N18: Total | O18: =SUM(O11:O17) -> 58304
A19: 40558 | B19: =AVERAGEIF(Dataset_A!$B:$B,'Extract Data_sheet'!$A19,Dataset_A!I:I) -> 1.5 | C19: =AVERAGEIF(Dataset_A!$B:$B,'Extract Data_sheet'!$A19,Dataset_A!J:J) -> 0.23333333 | D19: =AVERAGEIF(Dataset_A!$B:$B,'Extract Data_sheet'!$A19,Dataset_A!K:K) -> 0.2481125 | E19: =AVERAGEIF(Dataset_A!$B:$B,'Extract Data_sheet'!$A19,Dataset_A!L:L) -> 0.49875 | F19: =AVERAGEIF(Dataset_A!$B:$B,'Extract Data_sheet'!$A19,Dataset_A!M:M) -> 0.1579625 | G19: =SUMIF(Dataset_A!$B:$B,'Extract Data_sheet'!$A19,Dataset_A!N:N) -> 222 | H19: =SUMIF(Dataset_A!$B:$B,'Extract Data_sheet'!$A19,Dataset_A!O:O) -> 1026 | I19: =SUMIF(Dataset_A!$B:$B,'Extract Data_sheet'!$A19,Dataset_A!P:P) -> 1248 | K19: =TEXT(A19,"dddd") -> Saturday | L19: =IF(E19>=80%,"High Humidity",IF(E19>=50%,"Mid Humidity",IF(E19>=30%,"Low Humidity",""))) -> Low Humidity
A20: 40559 | B20: =AVERAGEIF(Dataset_A!$B:$B,'Extract Data_sheet'!$A20,Dataset_A!I:I) -> 1.2083333 | C20: =AVERAGEIF(Dataset_A!$B:$B,'Extract Data_sheet'!$A20,Dataset_A!J:J) -> 0.23166667 | D20: =AVERAGEIF(Dataset_A!$B:$B,'Extract Data_sheet'!$A20,Dataset_A!K:K) -> 0.23421667 | E20: =AVERAGEIF(Dataset_A!$B:$B,'Extract Data_sheet'!$A20,Dataset_A!L:L) -> 0.48375 | F20: =AVERAGEIF(Dataset_A!$B:$B,'Extract Data_sheet'!$A20,Dataset_A!M:M) -> 0.18843333 | G20: =SUMIF(Dataset_A!$B:$B,'Extract Data_sheet'!$A20,Dataset_A!N:N) -> 251 | H20: =SUMIF(Dataset_A!$B:$B,'Extract Data_sheet'!$A20,Dataset_A!O:O) -> 953 | I20: =SUMIF(Dataset_A!$B:$B,'Extract Data_sheet'!$A20,Dataset_A!P:P) -> 1204 | K20: =TEXT(A20,"dddd") -> Sunday | L20: =IF(E20>=80%,"High Humidity",IF(E20>=50%,"Mid Humidity",IF(E20>=30%,"Low Humidity",""))) -> Low Humidity
A21: 40560 | B21: =AVERAGEIF(Dataset_A!$B:$B,'Extract Data_sheet'!$A21,Dataset_A!I:I) -> 2.1666667 | C21: =AVERAGEIF(Dataset_A!$B:$B,'Extract Data_sheet'!$A21,Dataset_A!J:J) -> 0.17583333 | D21: =AVERAGEIF(Dataset_A!$B:$B,'Extract Data_sheet'!$A21,Dataset_A!K:K) -> 0.17677083 | E21: =AVERAGEIF(Dataset_A!$B:$B,'Extract Data_sheet'!$A21,Dataset_A!L:L) -> 0.5375 | F21: =AVERAGEIF(Dataset_A!$B:$B,'Extract Data_sheet'!$A21,Dataset_A!M:M) -> 0.19401667 | G21: =SUMIF(Dataset_A!$B:$B,'Extract Data_sheet'!$A21,Dataset_A!N:N) -> 117 | H21: =SUMIF(Dataset_A!$B:$B,'Extract Data_sheet'!$A21,Dataset_A!O:O) -> 883 | I21: =SUMIF(Dataset_A!$B:$B,'Extract Data_sheet'!$A21,Dataset_A!P:P) -> 1000 | K21: =TEXT(A21,"dddd") -> Monday | L21: =IF(E21>=80%,"High Humidity",IF(E21>=50%,"Mid Humidity",IF(E21>=30%,"Low Humidity",""))) -> Mid Humidity | N21: Low Humidity | O21: =SUMIF($L$5:$L$49,$N21,$I$5:$I$49) -> 21819 | Q21: KPI
A22: 40561 | B22: =AVERAGEIF(Dataset_A!$B:$B,'Extract Data_sheet'!$A22,Dataset_A!I:I) -> 2 | C22: =AVERAGEIF(Dataset_A!$B:$B,'Extract Data_sheet'!$A22,Dataset_A!J:J) -> 0.21666667 | D22: =AVERAGEIF(Dataset_A!$B:$B,'Extract Data_sheet'!$A22,Dataset_A!K:K) -> 0.23233333 | E22: =AVERAGEIF(Dataset_A!$B:$B,'Extract Data_sheet'!$A22,Dataset_A!L:L) -> 0.86166667 | F22: =AVERAGEIF(Dataset_A!$B:$B,'Extract Data_sheet'!$A22,Dataset_A!M:M) -> 0.146775 | G22: =SUMIF(Dataset_A!$B:$B,'Extract Data_sheet'!$A22,Dataset_A!N:N) -> 9 | H22: =SUMIF(Dataset_A!$B:$B,'Extract Data_sheet'!$A22,Dataset_A!O:O) -> 674 | I22: =SUMIF(Dataset_A!$B:$B,'Extract Data_sheet'!$A22,Dataset_A!P:P) -> 683 | K22: =TEXT(A22,"dddd") -> Tuesday | L22: =IF(E22>=80%,"High Humidity",IF(E22>=50%,"Mid Humidity",IF(E22>=30%,"Low Humidity",""))) -> High Humidity | N22: Mid Humidity | O22: =SUMIF($L$5:$L$49,$N22,$I$5:$I$49) -> 31946 | Q22: Total Client | S22: =O18 -> 58304
A23: 40562 | B23: =AVERAGEIF(Dataset_A!$B:$B,'Extract Data_sheet'!$A23,Dataset_A!I:I) -> 1.6521739 | C23: =AVERAGEIF(Dataset_A!$B:$B,'Extract Data_sheet'!$A23,Dataset_A!J:J) -> 0.29217391 | D23: =AVERAGEIF(Dataset_A!$B:$B,'Extract Data_sheet'!$A23,Dataset_A!K:K) -> 0.29842174 | E23: =AVERAGEIF(Dataset_A!$B:$B,'Extract Data_sheet'!$A23,Dataset_A!L:L) -> 0.74173913 | F23: =AVERAGEIF(Dataset_A!$B:$B,'Extract Data_sheet'!$A23,Dataset_A!M:M) -> 0.20831739 | G23: =SUMIF(Dataset_A!$B:$B,'Extract Data_sheet'!$A23,Dataset_A!N:N) -> 78 | H23: =SUMIF(Dataset_A!$B:$B,'Extract Data_sheet'!$A23,Dataset_A!O:O) -> 1572 | I23: =SUMIF(Dataset_A!$B:$B,'Extract Data_sheet'!$A23,Dataset_A!P:P) -> 1650 | K23: =TEXT(A23,"dddd") -> Wednesday | L23: =IF(E23>=80%,"High Humidity",IF(E23>=50%,"Mid Humidity",IF(E23>=30%,"Low Humidity",""))) -> Mid Humidity | N23: High Humidity | O23: =SUMIF($L$5:$L$49,$N23,$I$5:$I$49) -> 4539 | Q23: Average Registered | S23: =AVERAGE(H5:H49) -> 1186.2889
A24: 40563 | B24: =AVERAGEIF(Dataset_A!$B:$B,'Extract Data_sheet'!$A24,Dataset_A!I:I) -> 1.5416667 | C24: =AVERAGEIF(Dataset_A!$B:$B,'Extract Data_sheet'!$A24,Dataset_A!J:J) -> 0.26166667 | D24: =AVERAGEIF(Dataset_A!$B:$B,'Extract Data_sheet'!$A24,Dataset_A!K:K) -> 0.25505 | E24: =AVERAGEIF(Dataset_A!$B:$B,'Extract Data_sheet'!$A24,Dataset_A!L:L) -> 0.53833333 | F24: =AVERAGEIF(Dataset_A!$B:$B,'Extract Data_sheet'!$A24,Dataset_A!M:M) -> 0.19590417 | G24: =SUMIF(Dataset_A!$B:$B,'Extract Data_sheet'!$A24,Dataset_A!N:N) -> 83 | H24: =SUMIF(Dataset_A!$B:$B,'Extract Data_sheet'!$A24,Dataset_A!O:O) -> 1844 | I24: =SUMIF(Dataset_A!$B:$B,'Extract Data_sheet'!$A24,Dataset_A!P:P) -> 1927 | K24: =TEXT(A24,"dddd") -> Thursday | L24: =IF(E24>=80%,"High Humidity",IF(E24>=50%,"Mid Humidity",IF(E24>=30%,"Low Humidity",""))) -> Mid Humidity | Q24: Average Casual | S24: =AVERAGE(G5:G49) -> 109.35556
A25: 40564 | B25: =AVERAGEIF(Dataset_A!$B:$B,'Extract Data_sheet'!$A25,Dataset_A!I:I) -> 1.2916667 | C25: =AVERAGEIF(Dataset_A!$B:$B,'Extract Data_sheet'!$A25,Dataset_A!J:J) -> 0.1775 | D25: =AVERAGEIF(Dataset_A!$B:$B,'Extract Data_sheet'!$A25,Dataset_A!K:K) -> 0.15783333 | E25: =AVERAGEIF(Dataset_A!$B:$B,'Extract Data_sheet'!$A25,Dataset_A!L:L) -> 0.45708333 | F25: =AVERAGEIF(Dataset_A!$B:$B,'Extract Data_sheet'!$A25,Dataset_A!M:M) -> 0.35324167 | G25: =SUMIF(Dataset_A!$B:$B,'Extract Data_sheet'!$A25,Dataset_A!N:N) -> 75 | H25: =SUMIF(Dataset_A!$B:$B,'Extract Data_sheet'!$A25,Dataset_A!O:O) -> 1468 | I25: =SUMIF(Dataset_A!$B:$B,'Extract Data_sheet'!$A25,Dataset_A!P:P) -> 1543 | K25: =TEXT(A25,"dddd") -> Friday | L25: =IF(E25>=80%,"High Humidity",IF(E25>=50%,"Mid Humidity",IF(E25>=30%,"Low Humidity",""))) -> Low Humidity | N25: Total | O25: =SUM(O21:O24) -> 58304
A26: 40565 | B26: =AVERAGEIF(Dataset_A!$B:$B,'Extract Data_sheet'!$A26,Dataset_A!I:I) -> 1.3478261 | C26: =AVERAGEIF(Dataset_A!$B:$B,'Extract Data_sheet'!$A26,Dataset_A!J:J) -> 0.059130435 | D26: =AVERAGEIF(Dataset_A!$B:$B,'Extract Data_sheet'!$A26,Dataset_A!K:K) -> 0.079069565 | E26: =AVERAGEIF(Dataset_A!$B:$B,'Extract Data_sheet'!$A26,Dataset_A!L:L) -> 0.4 | F26: =AVERAGEIF(Dataset_A!$B:$B,'Extract Data_sheet'!$A26,Dataset_A!M:M) -> 0.17196957 | G26: =SUMIF(Dataset_A!$B:$B,'Extract Data_sheet'!$A26,Dataset_A!N:N) -> 93 | H26: =SUMIF(Dataset_A!$B:$B,'Extract Data_sheet'!$A26,Dataset_A!O:O) -> 888 | I26: =SUMIF(Dataset_A!$B:$B,'Extract Data_sheet'!$A26,Dataset_A!P:P) -> 981 | K26: =TEXT(A26,"dddd") -> Saturday | L26: =IF(E26>=80%,"High Humidity",IF(E26>=50%,"Mid Humidity",IF(E26>=30%,"Low Humidity",""))) -> Low Humidity
A27: 40566 | B27: =AVERAGEIF(Dataset_A!$B:$B,'Extract Data_sheet'!$A27,Dataset_A!I:I) -> 1.0869565 | C27: =AVERAGEIF(Dataset_A!$B:$B,'Extract Data_sheet'!$A27,Dataset_A!J:J) -> 0.096521739 | D27: =AVERAGEIF(Dataset_A!$B:$B,'Extract Data_sheet'!$A27,Dataset_A!K:K) -> 0.09883913 | E27: =AVERAGEIF(Dataset_A!$B:$B,'Extract Data_sheet'!$A27,Dataset_A!L:L) -> 0.43652174 | F27: =AVERAGEIF(Dataset_A!$B:$B,'Extract Data_sheet'!$A27,Dataset_A!M:M) -> 0.2466 | G27: =SUMIF(Dataset_A!$B:$B,'Extract Data_sheet'!$A27,Dataset_A!N:N) -> 150 | H27: =SUMIF(Dataset_A!$B:$B,'Extract Data_sheet'!$A27,Dataset_A!O:O) -> 836 | I27: =SUMIF(Dataset_A!$B:$B,'Extract Data_sheet'!$A27,Dataset_A!P:P) -> 986 | K27: =TEXT(A27,"dddd") -> Sunday | L27: =IF(E27>=80%,"High Humidity",IF(E27>=50%,"Mid Humidity",IF(E27>=30%,"Low Humidity",""))) -> Low Humidity
A28: 40567 | B28: =AVERAGEIF(Dataset_A!$B:$B,'Extract Data_sheet'!$A28,Dataset_A!I:I) -> 1.2173913 | C28: =AVERAGEIF(Dataset_A!$B:$B,'Extract Data_sheet'!$A28,Dataset_A!J:J) -> 0.097391304 | D28: =AVERAGEIF(Dataset_A!$B:$B,'Extract Data_sheet'!$A28,Dataset_A!K:K) -> 0.11793043 | E28: =AVERAGEIF(Dataset_A!$B:$B,'Extract Data_sheet'!$A28,Dataset_A!L:L) -> 0.49173913 | F28: =AVERAGEIF(Dataset_A!$B:$B,'Extract Data_sheet'!$A28,Dataset_A!M:M) -> 0.15833043 | G28: =SUMIF(Dataset_A!$B:$B,'Extract Data_sheet'!$A28,Dataset_A!N:N) -> 86 | H28: =SUMIF(Dataset_A!$B:$B,'Extract Data_sheet'!$A28,Dataset_A!O:O) -> 1330 | I28: =SUMIF(Dataset_A!$B:$B,'Extract Data_sheet'!$A28,Dataset_A!P:P) -> 1416 | K28: =TEXT(A28,"dddd") -> Monday | L28: =IF(E28>=80%,"High Humidity",IF(E28>=50%,"Mid Humidity",IF(E28>=30%,"Low Humidity",""))) -> Low Humidity | M28: 1 | N28: Date | O28: 40544 | P28: Please Enter Date
A29: 40568 | B29: =AVERAGEIF(Dataset_A!$B:$B,'Extract Data_sheet'!$A29,Dataset_A!I:I) -> 1.6086957 | C29: =AVERAGEIF(Dataset_A!$B:$B,'Extract Data_sheet'!$A29,Dataset_A!J:J) -> 0.22347826 | D29: =AVERAGEIF(Dataset_A!$B:$B,'Extract Data_sheet'!$A29,Dataset_A!K:K) -> 0.23452609 | E29: =AVERAGEIF(Dataset_A!$B:$B,'Extract Data_sheet'!$A29,Dataset_A!L:L) -> 0.61695652 | F29: =AVERAGEIF(Dataset_A!$B:$B,'Extract Data_sheet'!$A29,Dataset_A!M:M) -> 0.12979565 | G29: =SUMIF(Dataset_A!$B:$B,'Extract Data_sheet'!$A29,Dataset_A!N:N) -> 186 | H29: =SUMIF(Dataset_A!$B:$B,'Extract Data_sheet'!$A29,Dataset_A!O:O) -> 1799 | I29: =SUMIF(Dataset_A!$B:$B,'Extract Data_sheet'!$A29,Dataset_A!P:P) -> 1985 | K29: =TEXT(A29,"dddd") -> Tuesday | L29: =IF(E29>=80%,"High Humidity",IF(E29>=50%,"Mid Humidity",IF(E29>=30%,"Low Humidity",""))) -> Mid Humidity | M29: 2 | N29: Day | O29: =VLOOKUP($O$28,$A$4:$L$49,MATCH(N29,$A$4:$L$4,0),0) -> Saturday
A30: 40569 | B30: =AVERAGEIF(Dataset_A!$B:$B,'Extract Data_sheet'!$A30,Dataset_A!I:I) -> 2.9375 | C30: =AVERAGEIF(Dataset_A!$B:$B,'Extract Data_sheet'!$A30,Dataset_A!J:J) -> 0.2175 | D30: =AVERAGEIF(Dataset_A!$B:$B,'Extract Data_sheet'!$A30,Dataset_A!K:K) -> 0.2036 | E30: =AVERAGEIF(Dataset_A!$B:$B,'Extract Data_sheet'!$A30,Dataset_A!L:L) -> 0.8625 | F30: =AVERAGEIF(Dataset_A!$B:$B,'Extract Data_sheet'!$A30,Dataset_A!M:M) -> 0.29385 | G30: =SUMIF(Dataset_A!$B:$B,'Extract Data_sheet'!$A30,Dataset_A!N:N) -> 34 | H30: =SUMIF(Dataset_A!$B:$B,'Extract Data_sheet'!$A30,Dataset_A!O:O) -> 472 | I30: =SUMIF(Dataset_A!$B:$B,'Extract Data_sheet'!$A30,Dataset_A!P:P) -> 506 | K30: =TEXT(A30,"dddd") -> Wednesday | L30: =IF(E30>=80%,"High Humidity",IF(E30>=50%,"Mid Humidity",IF(E30>=30%,"Low Humidity",""))) -> High Humidity | M30: 3 | N30: Temp | O30: =VLOOKUP($O$28,$A$4:$L$49,MATCH(N30,$A$4:$L$4,0),0) -> 0.34416667
A31: 40570 | B31: =AVERAGEIF(Dataset_A!$B:$B,'Extract Data_sheet'!$A31,Dataset_A!I:I) -> 1 | C31: =AVERAGEIF(Dataset_A!$B:$B,'Extract Data_sheet'!$A31,Dataset_A!J:J) -> 0.195 | D31: =AVERAGEIF(Dataset_A!$B:$B,'Extract Data_sheet'!$A31,Dataset_A!K:K) -> 0.2197 | E31: =AVERAGEIF(Dataset_A!$B:$B,'Extract Data_sheet'!$A31,Dataset_A!L:L) -> 0.6875 | F31: =AVERAGEIF(Dataset_A!$B:$B,'Extract Data_sheet'!$A31,Dataset_A!M:M) -> 0.1138375 | G31: =SUMIF(Dataset_A!$B:$B,'Extract Data_sheet'!$A31,Dataset_A!N:N) -> 15 | H31: =SUMIF(Dataset_A!$B:$B,'Extract Data_sheet'!$A31,Dataset_A!O:O) -> 416 | I31: =SUMIF(Dataset_A!$B:$B,'Extract Data_sheet'!$A31,Dataset_A!P:P) -> 431 | K31: =TEXT(A31,"dddd") -> Thursday | L31: =IF(E31>=80%,"High Humidity",IF(E31>=50%,"Mid Humidity",IF(E31>=30%,"Low Humidity",""))) -> Mid Humidity | M31: 4 | N31: Humidity | O31: =VLOOKUP($O$28,$A$4:$L$49,MATCH(N31,$A$4:$L$4,0),0) -> 0.80583333
A32: 40571 | B32: =AVERAGEIF(Dataset_A!$B:$B,'Extract Data_sheet'!$A32,Dataset_A!I:I) -> 2.0434783 | C32: =AVERAGEIF(Dataset_A!$B:$B,'Extract Data_sheet'!$A32,Dataset_A!J:J) -> 0.20347826 | D32: =AVERAGEIF(Dataset_A!$B:$B,'Extract Data_sheet'!$A32,Dataset_A!K:K) -> 0.22331739 | E32: =AVERAGEIF(Dataset_A!$B:$B,'Extract Data_sheet'!$A32,Dataset_A!L:L) -> 0.79304348 | F32: =AVERAGEIF(Dataset_A!$B:$B,'Extract Data_sheet'!$A32,Dataset_A!M:M) -> 0.1233 | G32: =SUMIF(Dataset_A!$B:$B,'Extract Data_sheet'!$A32,Dataset_A!N:N) -> 38 | H32: =SUMIF(Dataset_A!$B:$B,'Extract Data_sheet'!$A32,Dataset_A!O:O) -> 1129 | I32: =SUMIF(Dataset_A!$B:$B,'Extract Data_sheet'!$A32,Dataset_A!P:P) -> 1167 | K32: =TEXT(A32,"dddd") -> Friday | L32: =IF(E32>=80%,"High Humidity",IF(E32>=50%,"Mid Humidity",IF(E32>=30%,"Low Humidity",""))) -> Mid Humidity | M32: 5 | N32: Hum Wise | O32: =VLOOKUP($O$28,$A$4:$L$49,MATCH(N32,$A$4:$L$4,0),0) -> High Humidity
A33: 40572 | B33: =AVERAGEIF(Dataset_A!$B:$B,'Extract Data_sheet'!$A33,Dataset_A!I:I) -> 1.2608696 | C33: =AVERAGEIF(Dataset_A!$B:$B,'Extract Data_sheet'!$A33,Dataset_A!J:J) -> 0.19652174 | D33: =AVERAGEIF(Dataset_A!$B:$B,'Extract Data_sheet'!$A33,Dataset_A!K:K) -> 0.21212609 | E33: =AVERAGEIF(Dataset_A!$B:$B,'Extract Data_sheet'!$A33,Dataset_A!L:L) -> 0.65173913 | F33: =AVERAGEIF(Dataset_A!$B:$B,'Extract Data_sheet'!$A33,Dataset_A!M:M) -> 0.14536522 | G33: =SUMIF(Dataset_A!$B:$B,'Extract Data_sheet'!$A33,Dataset_A!N:N) -> 123 | H33: =SUMIF(Dataset_A!$B:$B,'Extract Data_sheet'!$A33,Dataset_A!O:O) -> 975 | I33: =SUMIF(Dataset_A!$B:$B,'Extract Data_sheet'!$A33,Dataset_A!P:P) -> 1098 | K33: =TEXT(A33,"dddd") -> Saturday | L33: =IF(E33>=80%,"High Humidity",IF(E33>=50%,"Mid Humidity",IF(E33>=30%,"Low Humidity",""))) -> Mid Humidity | M33: 6 | N33: Casual | O33: =VLOOKUP($O$28,$A$4:$L$49,MATCH(N33,$A$4:$L$4,0),0) -> 331
A34: 40573 | B34: =AVERAGEIF(Dataset_A!$B:$B,'Extract Data_sheet'!$A34,Dataset_A!I:I) -> 1.3043478 | C34: =AVERAGEIF(Dataset_A!$B:$B,'Extract Data_sheet'!$A34,Dataset_A!J:J) -> 0.21652174 | D34: =AVERAGEIF(Dataset_A!$B:$B,'Extract Data_sheet'!$A34,Dataset_A!K:K) -> 0.25032174 | E34: =AVERAGEIF(Dataset_A!$B:$B,'Extract Data_sheet'!$A34,Dataset_A!L:L) -> 0.72217391 | F34: =AVERAGEIF(Dataset_A!$B:$B,'Extract Data_sheet'!$A34,Dataset_A!M:M) -> 0.073982609 | G34: =SUMIF(Dataset_A!$B:$B,'Extract Data_sheet'!$A34,Dataset_A!N:N) -> 140 | H34: =SUMIF(Dataset_A!$B:$B,'Extract Data_sheet'!$A34,Dataset_A!O:O) -> 956 | I34: =SUMIF(Dataset_A!$B:$B,'Extract Data_sheet'!$A34,Dataset_A!P:P) -> 1096 | K34: =TEXT(A34,"dddd") -> Sunday | L34: =IF(E34>=80%,"High Humidity",IF(E34>=50%,"Mid Humidity",IF(E34>=30%,"Low Humidity",""))) -> Mid Humidity | M34: 7 | N34: Registered | O34: =VLOOKUP($O$28,$A$4:$L$49,MATCH(N34,$A$4:$L$4,0),0) -> 654
A35: 40574 | B35: =AVERAGEIF(Dataset_A!$B:$B,'Extract Data_sheet'!$A35,Dataset_A!I:I) -> 1.7916667 | C35: =AVERAGEIF(Dataset_A!$B:$B,'Extract Data_sheet'!$A35,Dataset_A!J:J) -> 0.18083333 | D35: =AVERAGEIF(Dataset_A!$B:$B,'Extract Data_sheet'!$A35,Dataset_A!K:K) -> 0.18625 | E35: =AVERAGEIF(Dataset_A!$B:$B,'Extract Data_sheet'!$A35,Dataset_A!L:L) -> 0.60375 | F35: =AVERAGEIF(Dataset_A!$B:$B,'Extract Data_sheet'!$A35,Dataset_A!M:M) -> 0.18719167 | G35: =SUMIF(Dataset_A!$B:$B,'Extract Data_sheet'!$A35,Dataset_A!N:N) -> 42 | H35: =SUMIF(Dataset_A!$B:$B,'Extract Data_sheet'!$A35,Dataset_A!O:O) -> 1459 | I35: =SUMIF(Dataset_A!$B:$B,'Extract Data_sheet'!$A35,Dataset_A!P:P) -> 1501 | K35: =TEXT(A35,"dddd") -> Monday | L35: =IF(E35>=80%,"High Humidity",IF(E35>=50%,"Mid Humidity",IF(E35>=30%,"Low Humidity",""))) -> Mid Humidity | M35: 8 | N35: Total_Client | O35: =VLOOKUP($O$28,$A$4:$L$49,MATCH(N35,$A$4:$L$4,0),0) -> 985
A36: 40575 | B36: =AVERAGEIF(Dataset_A!$B:$B,'Extract Data_sheet'!$A36,Dataset_A!I:I) -> 2.2173913 | C36: =AVERAGEIF(Dataset_A!$B:$B,'Extract Data_sheet'!$A36,Dataset_A!J:J) -> 0.19217391 | D36: =AVERAGEIF(Dataset_A!$B:$B,'Extract Data_sheet'!$A36,Dataset_A!K:K) -> 0.23453043 | E36: =AVERAGEIF(Dataset_A!$B:$B,'Extract Data_sheet'!$A36,Dataset_A!L:L) -> 0.82956522 | F36: =AVERAGEIF(Dataset_A!$B:$B,'Extract Data_sheet'!$A36,Dataset_A!M:M) -> 0.053213043 | G36: =SUMIF(Dataset_A!$B:$B,'Extract Data_sheet'!$A36,Dataset_A!N:N) -> 47 | H36: =SUMIF(Dataset_A!$B:$B,'Extract Data_sheet'!$A36,Dataset_A!O:O) -> 1313 | I36: =SUMIF(Dataset_A!$B:$B,'Extract Data_sheet'!$A36,Dataset_A!P:P) -> 1360 | K36: =TEXT(A36,"dddd") -> Tuesday | L36: =IF(E36>=80%,"High Humidity",IF(E36>=50%,"Mid Humidity",IF(E36>=30%,"Low Humidity",""))) -> High Humidity
A37: 40576 | B37: =AVERAGEIF(Dataset_A!$B:$B,'Extract Data_sheet'!$A37,Dataset_A!I:I) -> 1.9166667 | C37: =AVERAGEIF(Dataset_A!$B:$B,'Extract Data_sheet'!$A37,Dataset_A!J:J) -> 0.26 | D37: =AVERAGEIF(Dataset_A!$B:$B,'Extract Data_sheet'!$A37,Dataset_A!K:K) -> 0.25441667 | E37: =AVERAGEIF(Dataset_A!$B:$B,'Extract Data_sheet'!$A37,Dataset_A!L:L) -> 0.77541667 | F37: =AVERAGEIF(Dataset_A!$B:$B,'Extract Data_sheet'!$A37,Dataset_A!M:M) -> 0.26430833 | G37: =SUMIF(Dataset_A!$B:$B,'Extract Data_sheet'!$A37,Dataset_A!N:N) -> 72 | H37: =SUMIF(Dataset_A!$B:$B,'Extract Data_sheet'!$A37,Dataset_A!O:O) -> 1454 | I37: =SUMIF(Dataset_A!$B:$B,'Extract Data_sheet'!$A37,Dataset_A!P:P) -> 1526 | K37: =TEXT(A37,"dddd") -> Wednesday | L37: =IF(E37>=80%,"High Humidity",IF(E37>=50%,"Mid Humidity",IF(E37>=30%,"Low Humidity",""))) -> Mid Humidity
A38: 40577 | B38: =AVERAGEIF(Dataset_A!$B:$B,'Extract Data_sheet'!$A38,Dataset_A!I:I) -> 1 | C38: =AVERAGEIF(Dataset_A!$B:$B,'Extract Data_sheet'!$A38,Dataset_A!J:J) -> 0.18695652 | D38: =AVERAGEIF(Dataset_A!$B:$B,'Extract Data_sheet'!$A38,Dataset_A!K:K) -> 0.17787826 | E38: =AVERAGEIF(Dataset_A!$B:$B,'Extract Data_sheet'!$A38,Dataset_A!L:L) -> 0.43782609 | F38: =AVERAGEIF(Dataset_A!$B:$B,'Extract Data_sheet'!$A38,Dataset_A!M:M) -> 0.27775217 | G38: =SUMIF(Dataset_A!$B:$B,'Extract Data_sheet'!$A38,Dataset_A!N:N) -> 61 | H38: =SUMIF(Dataset_A!$B:$B,'Extract Data_sheet'!$A38,Dataset_A!O:O) -> 1489 | I38: =SUMIF(Dataset_A!$B:$B,'Extract Data_sheet'!$A38,Dataset_A!P:P) -> 1550 | K38: =TEXT(A38,"dddd") -> Thursday | L38: =IF(E38>=80%,"High Humidity",IF(E38>=50%,"Mid Humidity",IF(E38>=30%,"Low Humidity",""))) -> Low Humidity
A39: 40578 | B39: =AVERAGEIF(Dataset_A!$B:$B,'Extract Data_sheet'!$A39,Dataset_A!I:I) -> 1.8695652 | C39: =AVERAGEIF(Dataset_A!$B:$B,'Extract Data_sheet'!$A39,Dataset_A!J:J) -> 0.21130435 | D39: =AVERAGEIF(Dataset_A!$B:$B,'Extract Data_sheet'!$A39,Dataset_A!K:K) -> 0.22858696 | E39: =AVERAGEIF(Dataset_A!$B:$B,'Extract Data_sheet'!$A39,Dataset_A!L:L) -> 0.58521739 | F39: =AVERAGEIF(Dataset_A!$B:$B,'Extract Data_sheet'!$A39,Dataset_A!M:M) -> 0.12783913 | G39: =SUMIF(Dataset_A!$B:$B,'Extract Data_sheet'!$A39,Dataset_A!N:N) -> 88 | H39: =SUMIF(Dataset_A!$B:$B,'Extract Data_sheet'!$A39,Dataset_A!O:O) -> 1620 | I39: =SUMIF(Dataset_A!$B:$B,'Extract Data_sheet'!$A39,Dataset_A!P:P) -> 1708 | K39: =TEXT(A39,"dddd") -> Friday | L39: =IF(E39>=80%,"High Humidity",IF(E39>=50%,"Mid Humidity",IF(E39>=30%,"Low Humidity",""))) -> Mid Humidity
A40: 40579 | B40: =AVERAGEIF(Dataset_A!$B:$B,'Extract Data_sheet'!$A40,Dataset_A!I:I) -> 2.375 | C40: =AVERAGEIF(Dataset_A!$B:$B,'Extract Data_sheet'!$A40,Dataset_A!J:J) -> 0.23333333 | D40: =AVERAGEIF(Dataset_A!$B:$B,'Extract Data_sheet'!$A40,Dataset_A!K:K) -> 0.24305833 | E40: =AVERAGEIF(Dataset_A!$B:$B,'Extract Data_sheet'!$A40,Dataset_A!L:L) -> 0.92916667 | F40: =AVERAGEIF(Dataset_A!$B:$B,'Extract Data_sheet'!$A40,Dataset_A!M:M) -> 0.16107917 | G40: =SUMIF(Dataset_A!$B:$B,'Extract Data_sheet'!$A40,Dataset_A!N:N) -> 100 | H40: =SUMIF(Dataset_A!$B:$B,'Extract Data_sheet'!$A40,Dataset_A!O:O) -> 905 | I40: =SUMIF(Dataset_A!$B:$B,'Extract Data_sheet'!$A40,Dataset_A!P:P) -> 1005 | K40: =TEXT(A40,"dddd") -> Saturday | L40: =IF(E40>=80%,"High Humidity",IF(E40>=50%,"Mid Humidity",IF(E40>=30%,"Low Humidity",""))) -> High Humidity
A41: 40580 | B41: =AVERAGEIF(Dataset_A!$B:$B,'Extract Data_sheet'!$A41,Dataset_A!I:I) -> 1 | C41: =AVERAGEIF(Dataset_A!$B:$B,'Extract Data_sheet'!$A41,Dataset_A!J:J) -> 0.28583333 | D41: =AVERAGEIF(Dataset_A!$B:$B,'Extract Data_sheet'!$A41,Dataset_A!K:K) -> 0.29167083 | E41: =AVERAGEIF(Dataset_A!$B:$B,'Extract Data_sheet'!$A41,Dataset_A!L:L) -> 0.56833333 | F41: =AVERAGEIF(Dataset_A!$B:$B,'Extract Data_sheet'!$A41,Dataset_A!M:M) -> 0.1418 | G41: =SUMIF(Dataset_A!$B:$B,'Extract Data_sheet'!$A41,Dataset_A!N:N) -> 354 | H41: =SUMIF(Dataset_A!$B:$B,'Extract Data_sheet'!$A41,Dataset_A!O:O) -> 1269 | I41: =SUMIF(Dataset_A!$B:$B,'Extract Data_sheet'!$A41,Dataset_A!P:P) -> 1623 | K41: =TEXT(A41,"dddd") -> Sunday | L41: =IF(E41>=80%,"High Humidity",IF(E41>=50%,"Mid Humidity",IF(E41>=30%,"Low Humidity",""))) -> Mid Humidity
A42: 40581 | B42: =AVERAGEIF(Dataset_A!$B:$B,'Extract Data_sheet'!$A42,Dataset_A!I:I) -> 1.4583333 | C42: =AVERAGEIF(Dataset_A!$B:$B,'Extract Data_sheet'!$A42,Dataset_A!J:J) -> 0.27166667 | D42: =AVERAGEIF(Dataset_A!$B:$B,'Extract Data_sheet'!$A42,Dataset_A!K:K) -> 0.30365833 | E42: =AVERAGEIF(Dataset_A!$B:$B,'Extract Data_sheet'!$A42,Dataset_A!L:L) -> 0.73833333 | F42: =AVERAGEIF(Dataset_A!$B:$B,'Extract Data_sheet'!$A42,Dataset_A!M:M) -> 0.045408333 | G42: =SUMIF(Dataset_A!$B:$B,'Extract Data_sheet'!$A42,Dataset_A!N:N) -> 120 | H42: =SUMIF(Dataset_A!$B:$B,'Extract Data_sheet'!$A42,Dataset_A!O:O) -> 1592 | I42: =SUMIF(Dataset_A!$B:$B,'Extract Data_sheet'!$A42,Dataset_A!P:P) -> 1712 | K42: =TEXT(A42,"dddd") -> Monday | L42: =IF(E42>=80%,"High Humidity",IF(E42>=50%,"Mid Humidity",IF(E42>=30%,"Low Humidity",""))) -> Mid Humidity
...

Sheet Pivot
A4: Sum of Total_Client | B4: Column Labels
A5: Row Labels | B5: Monday | C5: Tuesday | D5: Wednesday | E5: Thursday | F5: Friday | G5: Saturday | H5: Sunday | I5: Grand Total
A6: 01-Jan | G6: 985 | I6: 985
A7: 02-Jan | H7: 801 | I7: 801
A8: 03-Jan | B8: 1349 | I8: 1349
A9: 04-Jan | C9: 1562 | I9: 1562
A10: 05-Jan | D10: 1600 | I10: 1600
A11: 06-Jan | E11: 1606 | I11: 1606
A12: 07-Jan | F12: 1510 | I12: 1510
A13: 08-Jan | G13: 959 | I13: 959
A14: 09-Jan | H14: 822 | I14: 822
A15: 10-Jan | B15: 1321 | I15: 1321
A16: 11-Jan | C16: 1263 | I16: 1263
A17: 12-Jan | D17: 1162 | I17: 1162
A18: 13-Jan | E18: 1406 | I18: 1406
A19: 14-Jan | F19: 1421 | I19: 1421
A20: 15-Jan | G20: 1248 | I20: 1248
A21: 16-Jan | H21: 1204 | I21: 1204
A22: 17-Jan | B22: 1000 | I22: 1000
A23: 18-Jan | C23: 683 | I23: 683
A24: 19-Jan | D24: 1650 | I24: 1650
A25: 20-Jan | E25: 1927 | I25: 1927
A26: 21-Jan | F26: 1543 | I26: 1543
A27: 22-Jan | G27: 981 | I27: 981
A28: 23-Jan | H28: 986 | I28: 986
A29: 24-Jan | B29: 1416 | I29: 1416
A30: 25-Jan | C30: 1985 | I30: 1985
A31: 26-Jan | D31: 506 | I31: 506
A32: 27-Jan | E32: 431 | I32: 431
A33: 28-Jan | F33: 1167 | I33: 1167
A34: 29-Jan | G34: 1098 | I34: 1098
A35: 30-Jan | H35: 1096 | I35: 1096
A36: 31-Jan | B36: 1501 | I36: 1501
A37: 01-Feb | C37: 1360 | I37: 1360
A38: 02-Feb | D38: 1526 | I38: 1526
A39: 03-Feb | E39: 1550 | I39: 1550
A40: 04-Feb | F40: 1708 | I40: 1708
A41: 05-Feb | G41: 1005 | I41: 1005
A42: 06-Feb | H42: 1623 | I42: 1623
A43: 07-Feb | B43: 1712 | I43: 1712
...

Sheet Forecast sheet
A1: date | B1: Total_Client | C1: Forecast(Total_Client) | D1: Lower Confidence Bound(Total_Client) | E1: Upper Confidence Bound(Total_Client)
A2: 40544 | B2: 985
A3: 40545 | B3: 801
A4: 40546 | B4: 1349
A5: 40547 | B5: 1562
A6: 40548 | B6: 1600
A7: 40549 | B7: 1606
A8: 40550 | B8: 1510
A9: 40551 | B9: 959
A10: 40552 | B10: 822
A11: 40553 | B11: 1321
A12: 40554 | B12: 1263
A13: 40555 | B13: 1162
... A45: 40587 | B45: 1589
A46: 40588 | B46: 151 | C46: 151 | D46: 151 | E46: 151
A47: 40589 | C47: =_xlfn.FORECAST.ETS(A47,$B$2:$B$46,$A$2:$A$46,1,1) -> 1387.2167 | D47: =C47-_xlfn.FORECAST.ETS.CONFINT(A47,$B$2:$B$46,$A$2:$A$46,0.95,1,1) -> 585.50543 | E47: =C47+_xlfn.FORECAST.ETS.CONFINT(A47,$B$2:$B$46,$A$2:$A$46,0.95,1,1) -> 2188.9281
A48: 40590 | C48: =_xlfn.FORECAST.ETS(A48,$B$2:$B$46,$A$2:$A$46,1,1) -> 1392.5598 | D48: =C48-_xlfn.FORECAST.ETS.CONFINT(A48,$B$2:$B$46,$A$2:$A$46,0.95,1,1) -> 586.7697 | E48: =C48+_xlfn.FORECAST.ETS.CONFINT(A48,$B$2:$B$46,$A$2:$A$46,0.95,1,1) -> 2198.3498
A49: 40591 | C49: =_xlfn.FORECAST.ETS(A49,$B$2:$B$46,$A$2:$A$46,1,1) -> 1397.9028 | D49: =C49-_xlfn.FORECAST.ETS.CONFINT(A49,$B$2:$B$46,$A$2:$A$46,0.95,1,1) -> 587.97397 | E49: =C49+_xlfn.FORECAST.ETS.CONFINT(A49,$B$2:$B$46,$A$2:$A$46,0.95,1,1) -> 2207.8316
A50: 40592 | C50: =_xlfn.FORECAST.ETS(A50,$B$2:$B$46,$A$2:$A$46,1,1) -> 1403.2458 | D50: =C50-_xlfn.FORECAST.ETS.CONFINT(A50,$B$2:$B$46,$A$2:$A$46,0.95,1,1) -> 589.11835 | E50: =C50+_xlfn.FORECAST.ETS.CONFINT(A50,$B$2:$B$46,$A$2:$A$46,0.95,1,1) -> 2217.3733
A51: 40593 | C51: =_xlfn.FORECAST.ETS(A51,$B$2:$B$46,$A$2:$A$46,1,1) -> 1408.5889 | D51: =C51-_xlfn.FORECAST.ETS.CONFINT(A51,$B$2:$B$46,$A$2:$A$46,0.95,1,1) -> 590.20299 | E51: =C51+_xlfn.FORECAST.ETS.CONFINT(A51,$B$2:$B$46,$A$2:$A$46,0.95,1,1) -> 2226.9747
A52: 40594 | C52: =_xlfn.FORECAST.ETS(A52,$B$2:$B$46,$A$2:$A$46,1,1) -> 1413.9319 | D52: =C52-_xlfn.FORECAST.ETS.CONFINT(A52,$B$2:$B$46,$A$2:$A$46,0.95,1,1) -> 591.22802 | E52: =C52+_xlfn.FORECAST.ETS.CONFINT(A52,$B$2:$B$46,$A$2:$A$46,0.95,1,1) -> 2236.6358
A53: 40595 | C53: =_xlfn.FORECAST.ETS(A53,$B$2:$B$46,$A$2:$A$46,1,1) -> 1419.2749 | D53: =C53-_xlfn.FORECAST.ETS.CONFINT(A53,$B$2:$B$46,$A$2:$A$46,0.95,1,1) -> 592.19361 | E53: =C53+_xlfn.FORECAST.ETS.CONFINT(A53,$B$2:$B$46,$A$2:$A$46,0.95,1,1) -> 2246.3562
A54: 40596 | C54: =_xlfn.FORECAST.ETS(A54,$B$2:$B$46,$A$2:$A$46,1,1) -> 1424.618 | D54: =C54-_xlfn.FORECAST.ETS.CONFINT(A54,$B$2:$B$46,$A$2:$A$46,0.95,1,1) -> 593.09992 | E54: =C54+_xlfn.FORECAST.ETS.CONFINT(A54,$B$2:$B$46,$A$2:$A$46,0.95,1,1) -> 2256.136
A55: 40597 | C55: =_xlfn.FORECAST.ETS(A55,$B$2:$B$46,$A$2:$A$46,1,1) -> 1429.961 | D55: =C55-_xlfn.FORECAST.ETS.CONFINT(A55,$B$2:$B$46,$A$2:$A$46,0.95,1,1) -> 593.94713 | E55: =C55+_xlfn.FORECAST.ETS.CONFINT(A55,$B$2:$B$46,$A$2:$A$46,0.95,1,1) -> 2265.9748
A56: 40598 | C56: =_xlfn.FORECAST.ETS(A56,$B$2:$B$46,$A$2:$A$46,1,1) -> 1435.304 | D56: =C56-_xlfn.FORECAST.ETS.CONFINT(A56,$B$2:$B$46,$A$2:$A$46,0.95,1,1) -> 594.73541 | E56: =C56+_xlfn.FORECAST.ETS.CONFINT(A56,$B$2:$B$46,$A$2:$A$46,0.95,1,1) -> 2275.8726
A57: 40599 | C57: =_xlfn.FORECAST.ETS(A57,$B$2:$B$46,$A$2:$A$46,1,1) -> 1440.647 | D57: =C57-_xlfn.FORECAST.ETS.CONFINT(A57,$B$2:$B$46,$A$2:$A$46,0.95,1,1) -> 595.46497 | E57: =C57+_xlfn.FORECAST.ETS.CONFINT(A57,$B$2:$B$46,$A$2:$A$46,0.95,1,1) -> 2285.8291
A58: 40600 | C58: =_xlfn.FORECAST.ETS(A58,$B$2:$B$46,$A$2:$A$46,1,1) -> 1445.9901 | D58: =C58-_xlfn.FORECAST.ETS.CONFINT(A58,$B$2:$B$46,$A$2:$A$46,0.95,1,1) -> 596.136 | E58: =C58+_xlfn.FORECAST.ETS.CONFINT(A58,$B$2:$B$46,$A$2:$A$46,0.95,1,1) -> 2295.8442

Sheet Dataset_A
A1: Instant | B1: Date | C1: Season | D1: Year | E1: Month | F1: Hr | G1: Holiday | H1: Weekday | I1: Weather_sit | J1: Temp | K1: A_Temp | L1: Humidity | M1: Wind_speed | N1: Casual | O1: Registered | P1: Total_Client | S1: Hr Wise
A2: 1 | B2: 40544 | C2: 1 | D2: 2011 | E2: January | F2: 0 | G2: FALSE | H2: Saturday | I2: 1 | J2: 0.24 | K2: 0.2879 | L2: 0.81 | M2: 0 | N2: 3 | O2: 13 | P2: 16 | S2: =IF(Dataset_A[[#This Row],[Hr]]>=19,"Evening Time",IF(Dataset_A[[#This Row],[Hr]]>=9,"Day Time",IF(Dataset_A[[#This Row],[Hr]]>=0,"Night Time",""))) -> Night Time
A3: 2 | B3: 40544 | C3: 1 | D3: 2011 | E3: January | F3: 1 | G3: FALSE | H3: Saturday | I3: 1 | J3: 0.22 | K3: 0.2727 | L3: 0.8 | M3: 0 | N3: 8 | O3: 32 | P3: 40 | S3: =IF(Dataset_A[[#This Row],[Hr]]>=19,"Evening Time",IF(Dataset_A[[#This Row],[Hr]]>=9,"Day Time",IF(Dataset_A[[#This Row],[Hr]]>=0,"Night Time",""))) -> Night Time | T3: Time Based Analisis
A4: 3 | B4: 40544 | C4: 1 | D4: 2011 | E4: January | F4: 2 | G4: FALSE | H4: Saturday | I4: 1 | J4: 0.22 | K4: 0.2727 | L4: 0.8 | M4: 0 | N4: 5 | O4: 27 | P4: 32 | S4: =IF(Dataset_A[[#This Row],[Hr]]>=19,"Evening Time",IF(Dataset_A[[#This Row],[Hr]]>=9,"Day Time",IF(Dataset_A[[#This Row],[Hr]]>=0,"Night Time",""))) -> Night Time | T4: 19--24 | U4: Evening Time
A5: 4 | B5: 40544 | C5: 1 | D5: 2011 | E5: January | F5: 3 | G5: FALSE | H5: Saturday | I5: 1 | J5: 0.24 | K5: 0.2879 | L5: 0.75 | M5: 0 | N5: 3 | O5: 10 | P5: 13 | S5: =IF(Dataset_A[[#This Row],[Hr]]>=19,"Evening Time",IF(Dataset_A[[#This Row],[Hr]]>=9,"Day Time",IF(Dataset_A[[#This Row],[Hr]]>=0,"Night Time",""))) -> Night Time | T5: 0--8 | U5: Night Time
A6: 5 | B6: 40544 | C6: 1 | D6: 2011 | E6: January | F6: 4 | G6: FALSE | H6: Saturday | I6: 1 | J6: 0.24 | K6: 0.2879 | L6: 0.75 | M6: 0 | N6: 0 | O6: 1 | P6: 1 | S6: =IF(Dataset_A[[#This Row],[Hr]]>=19,"Evening Time",IF(Dataset_A[[#This Row],[Hr]]>=9,"Day Time",IF(Dataset_A[[#This Row],[Hr]]>=0,"Night Time",""))) -> Night Time | T6: 9--18 | U6: Day Time
A7: 6 | B7: 40544 | C7: 1 | D7: 2011 | E7: January | F7: 5 | G7: FALSE | H7: Saturday | I7: 2 | J7: 0.24 | K7: 0.2576 | L7: 0.75 | M7: 0.0896 | N7: 0 | O7: 1 | P7: 1 | S7: =IF(Dataset_A[[#This Row],[Hr]]>=19,"Evening Time",IF(Dataset_A[[#This Row],[Hr]]>=9,"Day Time",IF(Dataset_A[[#This Row],[Hr]]>=0,"Night Time",""))) -> Night Time
A8: 7 | B8: 40544 | C8: 1 | D8: 2011 | E8: January | F8: 6 | G8: FALSE | H8: Saturday | I8: 1 | J8: 0.22 | K8: 0.2727 | L8: 0.8 | M8: 0 | N8: 2 | O8: 0 | P8: 2 | S8: =IF(Dataset_A[[#This Row],[Hr]]>=19,"Evening Time",IF(Dataset_A[[#This Row],[Hr]]>=9,"Day Time",IF(Dataset_A[[#This Row],[Hr]]>=0,"Night Time",""))) -> Night Time
A9: 8 | B9: 40544 | C9: 1 | D9: 2011 | E9: January | F9: 7 | G9: FALSE | H9: Saturday | I9: 1 | J9: 0.2 | K9: 0.2576 | L9: 0.86 | M9: 0 | N9: 1 | O9: 2 | P9: 3 | S9: =IF(Dataset_A[[#This Row],[Hr]]>=19,"Evening Time",IF(Dataset_A[[#This Row],[Hr]]>=9,"Day Time",IF(Dataset_A[[#This Row],[Hr]]>=0,"Night Time",""))) -> Night Time
A10: 9 | B10: 40544 | C10: 1 | D10: 2011 | E10: January | F10: 8 | G10: FALSE | H10: Saturday | I10: 1 | J10: 0.24 | K10: 0 | L10: 0.75 | M10: 0 | N10: 1 | O10: 7 | P10: 8 | S10: =IF(Dataset_A[[#This Row],[Hr]]>=19,"Evening Time",IF(Dataset_A[[#This Row],[Hr]]>=9,"Day Time",IF(Dataset_A[[#This Row],[Hr]]>=0,"Night Time",""))) -> Night Time
A11: 10 | B11: 40544 | C11: 1 | D11: 2011 | E11: January | F11: 9 | G11: FALSE | H11: Saturday | I11: 1 | J11: 0.32 | K11: 0.3485 | L11: 0.76 | M11: 0 | N11: 8 | O11: 6 | P11: 14 | S11: =IF(Dataset_A[[#This Row],[Hr]]>=19,"Evening Time",IF(Dataset_A[[#This Row],[Hr]]>=9,"Day Time",IF(Dataset_A[[#This Row],[Hr]]>=0,"Night Time",""))) -> Day Time
A12: 11 | B12: 40544 | C12: 1 | D12: 2011 | E12: January | F12: 10 | G12: FALSE | H12: Saturday | I12: 1 | J12: 0.38 | K12: 0.3939 | L12: 0.76 | M12: 0.2537 | N12: 12 | O12: 24 | P12: 36 | S12: =IF(Dataset_A[[#This Row],[Hr]]>=19,"Evening Time",IF(Dataset_A[[#This Row],[Hr]]>=9,"Day Time",IF(Dataset_A[[#This Row],[Hr]]>=0,"Night Time",""))) -> Day Time
A13: 12 | B13: 40544 | C13: 1 | D13: 2011 | E13: January | F13: 11 | G13: FALSE | H13: Saturday | I13: 1 | J13: 0.36 | K13: 0.3333 | L13: 0.81 | M13: 0.2836 | N13: 26 | O13: 30 | P13: 56 | S13: =IF(Dataset_A[[#This Row],[Hr]]>=19,"Evening Time",IF(Dataset_A[[#This Row],[Hr]]>=9,"Day Time",IF(Dataset_A[[#This Row],[Hr]]>=0,"Night Time",""))) -> Day Time
A14: 13 | B14: 40544 | C14: 1 | D14: 2011 | E14: January | F14: 12 | G14: FALSE | H14: Saturday | I14: 1 | J14: 0.42 | K14: 0.4242 | L14: 0.77 | M14: 0.2836 | N14: 29 | O14: 55 | P14: 84 | S14: =IF(Dataset_A[[#This Row],[Hr]]>=19,"Evening Time",IF(Dataset_A[[#This Row],[Hr]]>=9,"Day Time",IF(Dataset_A[[#This Row],[Hr]]>=0,"Night Time",""))) -> Day Time
A15: 14 | B15: 40544 | C15: 1 | D15: 2011 | E15: January | F15: 13 | G15: FALSE | H15: Saturday | I15: 2 | J15: 0.46 | K15: 0.4545 | L15: 0.72 | M15: 0.2985 | N15: 47 | O15: 47 | P15: 94 | S15: =IF(Dataset_A[[#This Row],[Hr]]>=19,"Evening Time",IF(Dataset_A[[#This Row],[Hr]]>=9,"Day Time",IF(Dataset_A[[#This Row],[Hr]]>=0,"Night Time",""))) -> Day Time
A16: 15 | B16: 40544 | C16: 1 | D16: 2011 | E16: January | F16: 14 | G16: FALSE | H16: Saturday | I16: 2 | J16: 0.46 | K16: 0.4545 | L16: 0.72 | M16: 0.2836 | N16: 35 | O16: 71 | P16: 106 | S16: =IF(Dataset_A[[#This Row],[Hr]]>=19,"Evening Time",IF(Dataset_A[[#This Row],[Hr]]>=9,"Day Time",IF(Dataset_A[[#This Row],[Hr]]>=0,"Night Time",""))) -> Day Time
A17: 16 | B17: 40544 | C17: 1 | D17: 2011 | E17: January | F17: 15 | G17: FALSE | H17: Saturday | I17: 2 | J17: 0.44 | K17: 0.4394 | L17: 0.77 | M17: 0.2985 | N17: 40 | O17: 70 | P17: 110 | S17: =IF(Dataset_A[[#This Row],[Hr]]>=19,"Evening Time",IF(Dataset_A[[#This Row],[Hr]]>=9,"Day Time",IF(Dataset_A[[#This Row],[Hr]]>=0,"Night Time",""))) -> Day Time
A18: 17 | B18: 40544 | C18: 1 | D18: 2011 | E18: January | F18: 16 | G18: FALSE | H18: Saturday | I18: 2 | J18: 0.42 | K18: 0.4242 | L18: 0.82 | M18: 0.2985 | N18: 41 | O18: 52 | P18: 93 | S18: =IF(Dataset_A[[#This Row],[Hr]]>=19,"Evening Time",IF(Dataset_A[[#This Row],[Hr]]>=9,"Day Time",IF(Dataset_A[[#This Row],[Hr]]>=0,"Night Time",""))) -> Day Time
... A1001: 1000 | B1001: 40572 | C1001: 1 | D1001: 2011 | E1001: January | F1001: 0 | G1001: FALSE | H1001: Saturday | I1001: 1 | J1001: 0.22 | K1001: 0.197 | L1001: 0.64 | M1001: 0.3582 | N1001: 2 | O1001: 26 | P1001: 28 | S1001: =IF(Dataset_A[[#This Row],[Hr]]>=19,"Evening Time",IF(Dataset_A[[#This Row],[Hr]]>=9,"Day Time",IF(Dataset_A[[#This Row],[Hr]]>=0,"Night Time",""))) -> Night Time

Sheet Merge_1&2
A1: Instant | B1: Date | C1: Season | D1: Year | E1: Month | F1: Hr | G1: Holiday | H1: Weekday | I1: Weather_sit | J1: Temp | K1: A_Temp | L1: Humidity | M1: Wind_speed | N1: Casual | O1: Registered | P1: Total_Client
A2: 1 | B2: 40544 | C2: 1 | D2: 2011 | E2: January | F2: 0 | G2: FALSE | H2: Saturday | I2: 1 | J2: 0.24 | K2: 0.2879 | L2: 0.81 | M2: 0 | N2: 3 | O2: 13 | P2: 16
A3: 2 | B3: 40544 | C3: 1 | D3: 2011 | E3: January | F3: 1 | G3: FALSE | H3: Saturday | I3: 1 | J3: 0.22 | K3: 0.2727 | L3: 0.8 | M3: 0 | N3: 8 | O3: 32 | P3: 40
A4: 3 | B4: 40544 | C4: 1 | D4: 2011 | E4: January | F4: 2 | G4: FALSE | H4: Saturday | I4: 1 | J4: 0.22 | K4: 0.2727 | L4: 0.8 | M4: 0 | N4: 5 | O4: 27 | P4: 32
A5: 4 | B5: 40544 | C5: 1 | D5: 2011 | E5: January | F5: 3 | G5: FALSE | H5: Saturday | I5: 1 | J5: 0.24 | K5: 0.2879 | L5: 0.75 | M5: 0 | N5: 3 | O5: 10 | P5: 13
A6: 5 | B6: 40544 | C6: 1 | D6: 2011 | E6: January | F6: 4 | G6: FALSE | H6: Saturday | I6: 1 | J6: 0.24 | K6: 0.2879 | L6: 0.75 | M6: 0 | N6: 0 | O6: 1 | P6: 1
A7: 6 | B7: 40544 | C7: 1 | D7: 2011 | E7: January | F7: 5 | G7: FALSE | H7: Saturday | I7: 2 | J7: 0.24 | K7: 0.2576 | L7: 0.75 | M7: 0.0896 | N7: 0 | O7: 1 | P7: 1
A8: 7 | B8: 40544 | C8: 1 | D8: 2011 | E8: January | F8: 6 | G8: FALSE | H8: Saturday | I8: 1 | J8: 0.22 | K8: 0.2727 | L8: 0.8 | M8: 0 | N8: 2 | O8: 0 | P8: 2
A9: 8 | B9: 40544 | C9: 1 | D9: 2011 | E9: January | F9: 7 | G9: FALSE | H9: Saturday | I9: 1 | J9: 0.2 | K9: 0.2576 | L9: 0.86 | M9: 0 | N9: 1 | O9: 2 | P9: 3
A10: 9 | B10: 40544 | C10: 1 | D10: 2011 | E10: January | F10: 8 | G10: FALSE | H10: Saturday | I10: 1 | J10: 0.24 | K10: 0 | L10: 0.75 | M10: 0 | N10: 1 | O10: 7 | P10: 8
A11: 10 | B11: 40544 | C11: 1 | D11: 2011 | E11: January | F11: 9 | G11: FALSE | H11: Saturday | I11: 1 | J11: 0.32 | K11: 0.3485 | L11: 0.76 | M11: 0 | N11: 8 | O11: 6 | P11: 14
A12: 11 | B12: 40544 | C12: 1 | D12: 2011 | E12: January | F12: 10 | G12: FALSE | H12: Saturday | I12: 1 | J12: 0.38 | K12: 0.3939 | L12: 0.76 | M12: 0.2537 | N12: 12 | O12: 24 | P12: 36
A13: 12 | B13: 40544 | C13: 1 | D13: 2011 | E13: January | F13: 11 | G13: FALSE | H13: Saturday | I13: 1 | J13: 0.36 | K13: 0.3333 | L13: 0.81 | M13: 0.2836 | N13: 26 | O13: 30 | P13: 56
... A611: 610 | B611: 40571 | C611: 1 | D611: 2011 | E611: January | F611: 15 | G611: FALSE | H611: Friday | I611: 2 | J611: 0.2 | K611: 0.2576 | L611: 0.86 | M611: 0 | N611: 1 | O611: 40 | P611: 41

Sheet dataset_2 Table
A1: Instant | B1: A_Temp | C1: Humidity | D1: Wind_speed | E1: Casual | F1: Registered | G1: Total_Client
A2: 1 | B2: 0.2879 | C2: 0.81 | D2: 0 | E2: 3 | F2: 13 | G2: 16
A3: 2 | B3: 0.2727 | C3: 0.8 | D3: 0 | E3: 8 | F3: 32 | G3: 40
A4: 3 | B4: 0.2727 | C4: 0.8 | D4: 0 | E4: 5 | F4: 27 | G4: 32
A5: 4 | B5: 0.2879 | C5: 0.75 | D5: 0 | E5: 3 | F5: 10 | G5: 13
A6: 5 | B6: 0.2879 | C6: 0.75 | D6: 0 | E6: 0 | F6: 1 | G6: 1
A7: 6 | B7: 0.2576 | C7: 0.75 | D7: 0.0896 | E7: 0 | F7: 1 | G7: 1
A8: 7 | B8: 0.2727 | C8: 0.8 | D8: 0 | E8: 2 | F8: 0 | G8: 2
A9: 8 | B9: 0.2576 | C9: 0.86 | D9: 0 | E9: 1 | F9: 2 | G9: 3
A10: 9 | B10: 0 | C10: 0.75 | D10: 0 | E10: 1 | F10: 7 | G10: 8
A11: 10 | B11: 0.3485 | C11: 0.76 | D11: 0 | E11: 8 | F11: 6 | G11: 14
A12: 11 | B12: 0.3939 | C12: 0.76 | D12: 0.2537 | E12: 12 | F12: 24 | G12: 36
A13: 12 | B13: 0.3333 | C13: 0.81 | D13: 0.2836 | E13: 26 | F13: 30 | G13: 56
... A611: 610 | B611: 0.2576 | C611: 0.86 | D611: 0 | E611: 1 | F611: 40 | G611: 41

Sheet dataset_1 Table
A1: Instant | B1: Date | C1: Season | D1: Year | E1: Month | F1: Hr | G1: Holiday | H1: Weekday | I1: Weather_sit | J1: Temp
A2: 1 | B2: 40544 | C2: 1 | D2: 2011 | E2: January | F2: 0 | G2: FALSE | H2: Saturday | I2: 1 | J2: 0.24
A3: 2 | B3: 40544 | C3: 1 | D3: 2011 | E3: January | F3: 1 | G3: FALSE | H3: Saturday | I3: 1 | J3: 0.22
A4: 3 | B4: 40544 | C4: 1 | D4: 2011 | E4: January | F4: 2 | G4: FALSE | H4: Saturday | I4: 1 | J4: 0.22
A5: 4 | B5: 40544 | C5: 1 | D5: 2011 | E5: January | F5: 3 | G5: FALSE | H5: Saturday | I5: 1 | J5: 0.24
A6: 5 | B6: 40544 | C6: 1 | D6: 2011 | E6: January | F6: 4 | G6: FALSE | H6: Saturday | I6: 1 | J6: 0.24
A7: 6 | B7: 40544 | C7: 1 | D7: 2011 | E7: January | F7: 5 | G7: FALSE | H7: Saturday | I7: 2 | J7: 0.24
A8: 7 | B8: 40544 | C8: 1 | D8: 2011 | E8: January | F8: 6 | G8: FALSE | H8: Saturday | I8: 1 | J8: 0.22
A9: 8 | B9: 40544 | C9: 1 | D9: 2011 | E9: January | F9: 7 | G9: FALSE | H9: Saturday | I9: 1 | J9: 0.2
A10: 9 | B10: 40544 | C10: 1 | D10: 2011 | E10: January | F10: 8 | G10: FALSE | H10: Saturday | I10: 1 | J10: 0.24
A11: 10 | B11: 40544 | C11: 1 | D11: 2011 | E11: January | F11: 9 | G11: FALSE | H11: Saturday | I11: 1 | J11: 0.32
A12: 11 | B12: 40544 | C12: 1 | D12: 2011 | E12: January | F12: 10 | G12: FALSE | H12: Saturday | I12: 1 | J12: 0.38
A13: 12 | B13: 40544 | C13: 1 | D13: 2011 | E13: January | F13: 11 | G13: FALSE | H13: Saturday | I13: 1 | J13: 0.36
... A611: 610 | B611: 40571 | C611: 1 | D611: 2011 | E611: January | F611: 15 | G611: FALSE | H611: Friday | I611: 2 | J611: 0.2

Sheet Raw_dataset_1
A1: Instant | B1: Date | C1: Season | D1: Year | E1: Month | F1: Hr | G1: Holiday | H1: Weekday | I1: Weather_sit | J1: Temp
A2: 1 | B2: 40544 | C2: 1 | D2: =YEAR(B2) -> 2011 | E2: =TEXT(B2,"MMMM") -> January | F2: 0 | G2: =IF(H2="Sunday",TRUE,FALSE) -> FALSE | H2: =TEXT(B2,"DDDD") -> Saturday | I2: 1 | J2: 0.24
A3: 2 | B3: 40544 | C3: 1 | D3: =YEAR(B3) -> 2011 | E3: =TEXT(B3,"MMMM") -> January | F3: 1 | G3: =IF(H3="Sunday",TRUE,FALSE) -> FALSE | H3: =TEXT(B3,"DDDD") -> Saturday | I3: 1 | J3: 0.22
A4: 3 | B4: 40544 | C4: 1 | D4: =YEAR(B4) -> 2011 | E4: =TEXT(B4,"MMMM") -> January | F4: 2 | G4: =IF(H4="Sunday",TRUE,FALSE) -> FALSE | H4: =TEXT(B4,"DDDD") -> Saturday | I4: 1 | J4: 0.22
A5: 4 | B5: 40544 | C5: 1 | D5: =YEAR(B5) -> 2011 | E5: =TEXT(B5,"MMMM") -> January | F5: 3 | G5: =IF(H5="Sunday",TRUE,FALSE) -> FALSE | H5: =TEXT(B5,"DDDD") -> Saturday | I5: 1 | J5: 0.24
A6: 5 | B6: 40544 | C6: 1 | D6: =YEAR(B6) -> 2011 | E6: =TEXT(B6,"MMMM") -> January | F6: 4 | G6: =IF(H6="Sunday",TRUE,FALSE) -> FALSE | H6: =TEXT(B6,"DDDD") -> Saturday | I6: 1 | J6: 0.24
A7: 6 | B7: 40544 | C7: 1 | D7: =YEAR(B7) -> 2011 | E7: =TEXT(B7,"MMMM") -> January | F7: 5 | G7: =IF(H7="Sunday",TRUE,FALSE) -> FALSE | H7: =TEXT(B7,"DDDD") -> Saturday | I7: 2 | J7: 0.24
A8: 7 | B8: 40544 | C8: 1 | D8: =YEAR(B8) -> 2011 | E8: =TEXT(B8,"MMMM") -> January | F8: 6 | G8: =IF(H8="Sunday",TRUE,FALSE) -> FALSE | H8: =TEXT(B8,"DDDD") -> Saturday | I8: 1 | J8: 0.22
A9: 8 | B9: 40544 | C9: 1 | D9: =YEAR(B9) -> 2011 | E9: =TEXT(B9,"MMMM") -> January | F9: 7 | G9: =IF(H9="Sunday",TRUE,FALSE) -> FALSE | H9: =TEXT(B9,"DDDD") -> Saturday | I9: 1 | J9: 0.2
A10: 9 | B10: 40544 | C10: 1 | D10: =YEAR(B10) -> 2011 | E10: =TEXT(B10,"MMMM") -> January | F10: 8 | G10: =IF(H10="Sunday",TRUE,FALSE) -> FALSE | H10: =TEXT(B10,"DDDD") -> Saturday | I10: 1 | J10: 0.24
A11: 10 | B11: 40544 | C11: 1 | D11: =YEAR(B11) -> 2011 | E11: =TEXT(B11,"MMMM") -> January | F11: 9 | G11: =IF(H11="Sunday",TRUE,FALSE) -> FALSE | H11: =TEXT(B11,"DDDD") -> Saturday | I11: 1 | J11: 0.32
A12: 11 | B12: 40544 | C12: 1 | D12: =YEAR(B12) -> 2011 | E12: =TEXT(B12,"MMMM") -> January | F12: 10 | G12: =IF(H12="Sunday",TRUE,FALSE) -> FALSE | H12: =TEXT(B12,"DDDD") -> Saturday | I12: 1 | J12: 0.38
A13: 12 | B13: 40544 | C13: 1 | D13: =YEAR(B13) -> 2011 | E13: =TEXT(B13,"MMMM") -> January | F13: 11 | G13: =IF(H13="Sunday",TRUE,FALSE) -> FALSE | H13: =TEXT(B13,"DDDD") -> Saturday | I13: 1 | J13: 0.36
... A611: 610 | B611: 40571 | C611: 1 | D611: =YEAR(B611) -> 2011 | E611: =TEXT(B611,"MMMM") -> January | F611: 15 | G611: =IF(H611="Sunday",TRUE,FALSE) -> FALSE | H611: =TEXT(B611,"DDDD") -> Friday | I611: 2 | J611: 0.2

Sheet Raw_dataset_2
A1: Instant | B1: A_Temp | C1: Humidity | D1: Wind_speed | E1: Casual | F1: Registered | G1: Total_Client
A2: 1 | B2: 0.2879 | C2: 0.81 | D2: 0 | E2: 3 | F2: 13 | G2: 16
A3: 2 | B3: 0.2727 | C3: 0.8 | D3: 0 | E3: 8 | F3: 32 | G3: 40
A4: 3 | B4: 0.2727 | C4: 0.8 | D4: 0 | E4: 5 | F4: 27 | G4: 32
A5: 4 | B5: 0.2879 | C5: 0.75 | D5: 0 | E5: 3 | F5: 10 | G5: 13
A6: 5 | B6: 0.2879 | C6: 0.75 | D6: 0 | E6: 0 | F6: 1 | G6: 1
A7: 6 | B7: 0.2576 | C7: 0.75 | D7: 0.0896 | E7: 0 | F7: 1 | G7: 1
A8: 7 | B8: 0.2727 | C8: 0.8 | D8: 0 | E8: 2 | F8: 0 | G8: 2
A9: 8 | B9: 0.2576 | C9: 0.86 | D9: 0 | E9: 1 | F9: 2 | G9: 3
A10: 9 | B10: 0 | C10: 0.75 | D10: 0 | E10: 1 | F10: 7 | G10: 8
A11: 10 | B11: 0.3485 | C11: 0.76 | D11: 0 | E11: 8 | F11: 6 | G11: 14
A12: 11 | B12: 0.3939 | C12: 0.76 | D12: 0.2537 | E12: 12 | F12: 24 | G12: 36
A13: 12 | B13: 0.3333 | C13: 0.81 | D13: 0.2836 | E13: 26 | F13: 30 | G13: 56
... A611: 610 | B611: 0.2576 | C611: 0.86 | D611: 0 | E611: 1 | F611: 40 | G611: 41

Sheet Raw_dataset_3
A1: Instant | B1: Date | C1: Season | D1: Year | E1: Month | F1: Hr | G1: Holiday | H1: Weekday | I1: Weather_sit | J1: Temp | K1: A_Temp | L1: Humidity | M1: Wind_speed | N1: Casual | O1: Registered | P1: Total_Client
A2: 611 | B2: 40572 | C2: 1 | D2: =YEAR(B2) -> 2011 | E2: =TEXT(B2,"mmmm") -> January | F2: 1 | G2: =IF(H2="Sunday",TRUE,FALSE) -> FALSE | H2: =TEXT(B2,"dddd") -> Saturday | I2: 1 | J2: 0.22 | K2: 0.2273 | L2: 0.64 | M2: 0.194 | N2: 0 | O2: 20 | P2: 20
A3: 612 | B3: 40572 | C3: 1 | D3: =YEAR(B3) -> 2011 | E3: =TEXT(B3,"mmmm") -> January | F3: 2 | G3: =IF(H3="Sunday",TRUE,FALSE) -> FALSE | H3: =TEXT(B3,"dddd") -> Saturday | I3: 1 | J3: 0.22 | K3: 0.2273 | L3: 0.64 | M3: 0.1642 | N3: 0 | O3: 15 | P3: 15
A4: 613 | B4: 40572 | C4: 1 | D4: =YEAR(B4) -> 2011 | E4: =TEXT(B4,"mmmm") -> January | F4: 3 | G4: =IF(H4="Sunday",TRUE,FALSE) -> FALSE | H4: =TEXT(B4,"dddd") -> Saturday | I4: 1 | J4: 0.2 | K4: 0.2121 | L4: 0.64 | M4: 0.1343 | N4: 3 | O4: 5 | P4: 8
A5: 614 | B5: 40572 | C5: 1 | D5: =YEAR(B5) -> 2011 | E5: =TEXT(B5,"mmmm") -> January | F5: 4 | G5: =IF(H5="Sunday",TRUE,FALSE) -> FALSE | H5: =TEXT(B5,"dddd") -> Saturday | I5: 1 | J5: 0.16 | K5: 0.1818 | L5: 0.69 | M5: 0.1045 | N5: 1 | O5: 2 | P5: 3
A6: 615 | B6: 40572 | C6: 1 | D6: =YEAR(B6) -> 2011 | E6: =TEXT(B6,"mmmm") -> January | F6: 6 | G6: =IF(H6="Sunday",TRUE,FALSE) -> FALSE | H6: =TEXT(B6,"dddd") -> Saturday | I6: 1 | J6: 0.16 | K6: 0.1818 | L6: 0.64 | M6: 0.1343 | N6: 0 | O6: 2 | P6: 2
A7: 616 | B7: 40572 | C7: 1 | D7: =YEAR(B7) -> 2011 | E7: =TEXT(B7,"mmmm") -> January | F7: 7 | G7: =IF(H7="Sunday",TRUE,FALSE) -> FALSE | H7: =TEXT(B7,"dddd") -> Saturday | I7: 1 | J7: 0.16 | K7: 0.1818 | L7: 0.59 | M7: 0.1045 | N7: 1 | O7: 4 | P7: 5
A8: 617 | B8: 40572 | C8: 1 | D8: =YEAR(B8) -> 2011 | E8: =TEXT(B8,"mmmm") -> January | F8: 8 | G8: =IF(H8="Sunday",TRUE,FALSE) -> FALSE | H8: =TEXT(B8,"dddd") -> Saturday | I8: 1 | J8: 0.18 | K8: 0.197 | L8: 0.55 | M8: 0.1642 | N8: 3 | O8: 31 | P8: 34
A9: 618 | B9: 40572 | C9: 1 | D9: =YEAR(B9) -> 2011 | E9: =TEXT(B9,"mmmm") -> January | F9: 9 | G9: =IF(H9="Sunday",TRUE,FALSE) -> FALSE | H9: =TEXT(B9,"dddd") -> Saturday | I9: 1 | J9: 0.18 | K9: 0.2121 | L9: 0.59 | M9: 0.0896 | N9: 0 | O9: 34 | P9: 34
A10: 619 | B10: 40572 | C10: 1 | D10: =YEAR(B10) -> 2011 | E10: =TEXT(B10,"mmmm") -> January | F10: 10 | G10: =IF(H10="Sunday",TRUE,FALSE) -> FALSE | H10: =TEXT(B10,"dddd") -> Saturday | I10: 2 | J10: 0.18 | K10: 0.2121 | L10: 0.64 | M10: 0.1045 | N10: 4 | O10: 51 | P10: 55
A11: 620 | B11: 40572 | C11: 1 | D11: =YEAR(B11) -> 2011 | E11: =TEXT(B11,"mmmm") -> January | F11: 11 | G11: =IF(H11="Sunday",TRUE,FALSE) -> FALSE | H11: =TEXT(B11,"dddd") -> Saturday | I11: 2 | J11: 0.18 | K11: 0.197 | L11: 0.64 | M11: 0.1343 | N11: 4 | O11: 60 | P11: 64
A12: 621 | B12: 40572 | C12: 1 | D12: =YEAR(B12) -> 2011 | E12: =TEXT(B12,"mmmm") -> January | F12: 12 | G12: =IF(H12="Sunday",TRUE,FALSE) -> FALSE | H12: =TEXT(B12,"dddd") -> Saturday | I12: 2 | J12: 0.2 | K12: 0.197 | L12: 0.59 | M12: 0.194 | N12: 12 | O12: 66 | P12: 78
A13: 622 | B13: 40572 | C13: 1 | D13: =YEAR(B13) -> 2011 | E13: =TEXT(B13,"mmmm") -> January | F13: 13 | G13: =IF(H13="Sunday",TRUE,FALSE) -> FALSE | H13: =TEXT(B13,"dddd") -> Saturday | I13: 2 | J13: 0.22 | K13: 0.2273 | L13: 0.55 | M13: 0.1642 | N13: 9 | O13: 56 | P13: 65
... A391: 1000 | B391: 40572 | C391: 1 | D391: =YEAR(B391) -> 2011 | E391: =TEXT(B391,"mmmm") -> January | F391: 0 | G391: =IF(H391="Sunday",TRUE,FALSE) -> FALSE | H391: =TEXT(B391,"dddd") -> Saturday | I391: 1 | J391: 0.22 | K391: 0.197 | L391: 0.64 | M391: 0.3582 | N391: 2 | O391: 26 | P391: 28
